2025-03-25 22:55:21,636 - ERROR - пїЅпїЅпїЅпїЅпїЅпїЅ пїЅпїЅпїЅпїЅпїЅпїЅ: ('Connection aborted.', RemoteDisconnected('Remote end closed connection without response'))
2025-03-25 23:10:00,922 - ERROR - пїЅпїЅпїЅпїЅпїЅпїЅ пїЅпїЅпїЅпїЅпїЅпїЅ: ('Connection aborted.', RemoteDisconnected('Remote end closed connection without response'))2025-04-08 20:09:45,101 - ERROR - Threaded polling exception: A request to the Telegram API was unsuccessful. Error code: 409. Description: Conflict: terminated by other getUpdates request; make sure that only one bot instance is running
2025-04-08 20:09:45,101 - ERROR - Exception traceback:
Traceback (most recent call last):
  File "C:\Users\dimon\AppData\Local\Programs\Python\Python311\Lib\site-packages\telebot\__init__.py", line 1234, in __threaded_polling
    polling_thread.raise_exceptions()
  File "C:\Users\dimon\AppData\Local\Programs\Python\Python311\Lib\site-packages\telebot\util.py", line 111, in raise_exceptions
    raise self.exception_info
  File "C:\Users\dimon\AppData\Local\Programs\Python\Python311\Lib\site-packages\telebot\util.py", line 93, in run
    task(*args, **kwargs)
  File "C:\Users\dimon\AppData\Local\Programs\Python\Python311\Lib\site-packages\telebot\__init__.py", line 688, in __retrieve_updates
    updates = self.get_updates(offset=(self.last_update_id + 1),
             ^^^^^^^^^^^^^^^^^^^^^^^^^^^^^^^^^^^^^^^^^^^^^^^^^^
  File "C:\Users\dimon\AppData\Local\Programs\Python\Python311\Lib\site-packages\telebot\__init__.py", line 660, in get_updates
    json_updates = apihelper.get_updates(
                   ^^^^^^^^^^^^^^^^^^^^^^
  File "C:\Users\dimon\AppData\Local\Programs\Python\Python311\Lib\site-packages\telebot\apihelper.py", line 332, in get_updates
    return _make_request(token, method_url, params=payload)
           ^^^^^^^^^^^^^^^^^^^^^^^^^^^^^^^^^^^^^^^^^^^^^^^^
  File "C:\Users\dimon\AppData\Local\Programs\Python\Python311\Lib\site-packages\telebot\apihelper.py", line 168, in _make_request
    json_result = _check_result(method_name, result)
                  ^^^^^^^^^^^^^^^^^^^^^^^^^^^^^^^^^^
  File "C:\Users\dimon\AppData\Local\Programs\Python\Python311\Lib\site-packages\telebot\apihelper.py", line 195, in _check_result
    raise ApiTelegramException(method_name, result, result_json)
telebot.apihelper.ApiTelegramException: A request to the Telegram API was unsuccessful. Error code: 409. Description: Conflict: terminated by other getUpdates request; make sure that only one bot instance is running

2025-04-08 20:09:53,785 - ERROR - Threaded polling exception: A request to the Telegram API was unsuccessful. Error code: 409. Description: Conflict: terminated by other getUpdates request; make sure that only one bot instance is running
2025-04-08 20:09:53,785 - ERROR - Exception traceback:
Traceback (most recent call last):
  File "C:\Users\dimon\AppData\Local\Programs\Python\Python311\Lib\site-packages\telebot\__init__.py", line 1234, in __threaded_polling
    polling_thread.raise_exceptions()
  File "C:\Users\dimon\AppData\Local\Programs\Python\Python311\Lib\site-packages\telebot\util.py", line 111, in raise_exceptions
    raise self.exception_info
  File "C:\Users\dimon\AppData\Local\Programs\Python\Python311\Lib\site-packages\telebot\util.py", line 93, in run
    task(*args, **kwargs)
  File "C:\Users\dimon\AppData\Local\Programs\Python\Python311\Lib\site-packages\telebot\__init__.py", line 688, in __retrieve_updates
    updates = self.get_updates(offset=(self.last_update_id + 1),
             ^^^^^^^^^^^^^^^^^^^^^^^^^^^^^^^^^^^^^^^^^^^^^^^^^^
  File "C:\Users\dimon\AppData\Local\Programs\Python\Python311\Lib\site-packages\telebot\__init__.py", line 660, in get_updates
    json_updates = apihelper.get_updates(
                   ^^^^^^^^^^^^^^^^^^^^^^
  File "C:\Users\dimon\AppData\Local\Programs\Python\Python311\Lib\site-packages\telebot\apihelper.py", line 332, in get_updates
    return _make_request(token, method_url, params=payload)
           ^^^^^^^^^^^^^^^^^^^^^^^^^^^^^^^^^^^^^^^^^^^^^^^^
  File "C:\Users\dimon\AppData\Local\Programs\Python\Python311\Lib\site-packages\telebot\apihelper.py", line 168, in _make_request
    json_result = _check_result(method_name, result)
                  ^^^^^^^^^^^^^^^^^^^^^^^^^^^^^^^^^^
  File "C:\Users\dimon\AppData\Local\Programs\Python\Python311\Lib\site-packages\telebot\apihelper.py", line 195, in _check_result
    raise ApiTelegramException(method_name, result, result_json)
telebot.apihelper.ApiTelegramException: A request to the Telegram API was unsuccessful. Error code: 409. Description: Conflict: terminated by other getUpdates request; make sure that only one bot instance is running

2025-04-08 20:09:59,519 - ERROR - Threaded polling exception: A request to the Telegram API was unsuccessful. Error code: 409. Description: Conflict: terminated by other getUpdates request; make sure that only one bot instance is running
2025-04-08 20:09:59,522 - ERROR - Exception traceback:
Traceback (most recent call last):
  File "C:\Users\dimon\AppData\Local\Programs\Python\Python311\Lib\site-packages\telebot\__init__.py", line 1234, in __threaded_polling
    polling_thread.raise_exceptions()
  File "C:\Users\dimon\AppData\Local\Programs\Python\Python311\Lib\site-packages\telebot\util.py", line 111, in raise_exceptions
    raise self.exception_info
  File "C:\Users\dimon\AppData\Local\Programs\Python\Python311\Lib\site-packages\telebot\util.py", line 93, in run
    task(*args, **kwargs)
  File "C:\Users\dimon\AppData\Local\Programs\Python\Python311\Lib\site-packages\telebot\__init__.py", line 688, in __retrieve_updates
    updates = self.get_updates(offset=(self.last_update_id + 1),
             ^^^^^^^^^^^^^^^^^^^^^^^^^^^^^^^^^^^^^^^^^^^^^^^^^^
  File "C:\Users\dimon\AppData\Local\Programs\Python\Python311\Lib\site-packages\telebot\__init__.py", line 660, in get_updates
    json_updates = apihelper.get_updates(
                   ^^^^^^^^^^^^^^^^^^^^^^
  File "C:\Users\dimon\AppData\Local\Programs\Python\Python311\Lib\site-packages\telebot\apihelper.py", line 332, in get_updates
    return _make_request(token, method_url, params=payload)
           ^^^^^^^^^^^^^^^^^^^^^^^^^^^^^^^^^^^^^^^^^^^^^^^^
  File "C:\Users\dimon\AppData\Local\Programs\Python\Python311\Lib\site-packages\telebot\apihelper.py", line 168, in _make_request
    json_result = _check_result(method_name, result)
                  ^^^^^^^^^^^^^^^^^^^^^^^^^^^^^^^^^^
  File "C:\Users\dimon\AppData\Local\Programs\Python\Python311\Lib\site-packages\telebot\apihelper.py", line 195, in _check_result
    raise ApiTelegramException(method_name, result, result_json)
telebot.apihelper.ApiTelegramException: A request to the Telegram API was unsuccessful. Error code: 409. Description: Conflict: terminated by other getUpdates request; make sure that only one bot instance is running

2025-04-08 20:10:04,127 - ERROR - Threaded polling exception: A request to the Telegram API was unsuccessful. Error code: 409. Description: Conflict: terminated by other getUpdates request; make sure that only one bot instance is running
2025-04-08 20:10:04,129 - ERROR - Exception traceback:
Traceback (most recent call last):
  File "C:\Users\dimon\AppData\Local\Programs\Python\Python311\Lib\site-packages\telebot\__init__.py", line 1234, in __threaded_polling
    polling_thread.raise_exceptions()
  File "C:\Users\dimon\AppData\Local\Programs\Python\Python311\Lib\site-packages\telebot\util.py", line 111, in raise_exceptions
    raise self.exception_info
  File "C:\Users\dimon\AppData\Local\Programs\Python\Python311\Lib\site-packages\telebot\util.py", line 93, in run
    task(*args, **kwargs)
  File "C:\Users\dimon\AppData\Local\Programs\Python\Python311\Lib\site-packages\telebot\__init__.py", line 688, in __retrieve_updates
    updates = self.get_updates(offset=(self.last_update_id + 1),
             ^^^^^^^^^^^^^^^^^^^^^^^^^^^^^^^^^^^^^^^^^^^^^^^^^^
  File "C:\Users\dimon\AppData\Local\Programs\Python\Python311\Lib\site-packages\telebot\__init__.py", line 660, in get_updates
    json_updates = apihelper.get_updates(
                   ^^^^^^^^^^^^^^^^^^^^^^
  File "C:\Users\dimon\AppData\Local\Programs\Python\Python311\Lib\site-packages\telebot\apihelper.py", line 332, in get_updates
    return _make_request(token, method_url, params=payload)
           ^^^^^^^^^^^^^^^^^^^^^^^^^^^^^^^^^^^^^^^^^^^^^^^^
  File "C:\Users\dimon\AppData\Local\Programs\Python\Python311\Lib\site-packages\telebot\apihelper.py", line 168, in _make_request
    json_result = _check_result(method_name, result)
                  ^^^^^^^^^^^^^^^^^^^^^^^^^^^^^^^^^^
  File "C:\Users\dimon\AppData\Local\Programs\Python\Python311\Lib\site-packages\telebot\apihelper.py", line 195, in _check_result
    raise ApiTelegramException(method_name, result, result_json)
telebot.apihelper.ApiTelegramException: A request to the Telegram API was unsuccessful. Error code: 409. Description: Conflict: terminated by other getUpdates request; make sure that only one bot instance is running

2025-04-08 20:16:08,125 - ERROR - Другая ошибка: ('Connection aborted.', RemoteDisconnected('Remote end closed connection without response'))
2025-04-08 21:35:33,338 - ERROR - Другая ошибка: ('Connection aborted.', RemoteDisconnected('Remote end closed connection without response'))
2025-04-08 21:58:28,454 - ERROR - Другая ошибка: ('Connection aborted.', RemoteDisconnected('Remote end closed connection without response'))
2025-04-08 23:21:33,806 - ERROR - Другая ошибка: ('Connection aborted.', RemoteDisconnected('Remote end closed connection without response'))
